<?xml version="1.0"?>
<robot name="platform_robot" xmlns:xacro="http://www.ros.org/wiki/xacro">

  <xacro:property name="body_length" value="0.32"/>
  <xacro:property name="body_width"  value="0.24"/>
  <xacro:property name="body_height" value="0.10"/>

  <xacro:property name="wheel_radius" value="0.05"/>
  <xacro:property name="wheel_width"  value="0.03"/>
  <xacro:property name="wheel_y"      value="0.115"/>
  <xacro:property name="wheel_z"      value="-0.05"/>

  <xacro:macro name="box_inertia" params="m x y z">
    <inertial>
      <mass value="${m}"/>
      <origin xyz="0 0 0" rpy="0 0 0"/>
      <inertia
        ixx="${m*(y*y+z*z)/12.0}"
        ixy="0.0"
        ixz="0.0"
        iyy="${m*(x*x+z*z)/12.0}"
        iyz="0.0"
        izz="${m*(x*x+y*y)/12.0}"/>
    </inertial>
  </xacro:macro>

  <xacro:macro name="cylinder_inertia" params="m r l">
    <inertial>
      <mass value="${m}"/>
      <origin xyz="0 0 0" rpy="0 0 0"/>
      <inertia
        ixx="${m*(3*r*r + l*l)/12.0}"
        ixy="0.0"
        ixz="0.0"
        iyy="${m*(3*r*r + l*l)/12.0}"
        iyz="0.0"
        izz="${0.5*m*r*r}"/>
    </inertial>
  </xacro:macro>

  <link name="base_link">
    <visual>
      <geometry>
        <box size="${body_length} ${body_width} ${body_height}"/>
      </geometry>
      <material name="green">
        <color rgba="0.20 0.65 0.35 1.0"/>
      </material>
    </visual>

    <collision>
      <geometry>
        <box size="${body_length} ${body_width} ${body_height}"/>
      </geometry>
    </collision>

    <xacro:box_inertia m="8.0" x="${body_length}" y="${body_width}" z="${body_height}"/>
  </link>

  <link name="left_wheel">
    <visual>
      <origin rpy="1.5708 0 0"/>
      <geometry>
        <cylinder radius="${wheel_radius}" length="${wheel_width}"/>
      </geometry>
      <material name="black">
        <color rgba="0.1 0.1 0.1 1.0"/>
      </material>
    </visual>
    <collision>
      <origin rpy="1.5708 0 0"/>
      <geometry>
        <cylinder radius="${wheel_radius}" length="${wheel_width}"/>
      </geometry>
    </collision>
    <xacro:cylinder_inertia m="0.8" r="${wheel_radius}" l="${wheel_width}"/>
  </link>

  <joint name="left_wheel_joint" type="continuous">
    <parent link="base_link"/>
    <child link="left_wheel"/>
    <origin xyz="0 ${wheel_y} ${wheel_z}" rpy="0 0 0"/>
    <axis xyz="0 1 0"/>
  </joint>

  <link name="right_wheel">
    <visual>
      <origin rpy="1.5708 0 0"/>
      <geometry>
        <cylinder radius="${wheel_radius}" length="${wheel_width}"/>
      </geometry>
      <material name="black">
        <color rgba="0.1 0.1 0.1 1.0"/>
      </material>
    </visual>
    <collision>
      <origin rpy="1.5708 0 0"/>
      <geometry>
        <cylinder radius="${wheel_radius}" length="${wheel_width}"/>
      </geometry>
    </collision>
    <xacro:cylinder_inertia m="0.8" r="${wheel_radius}" l="${wheel_width}"/>
  </link>

  <joint name="right_wheel_joint" type="continuous">
    <parent link="base_link"/>
    <child link="right_wheel"/>
    <origin xyz="0 -${wheel_y} ${wheel_z}" rpy="0 0 0"/>
    <axis xyz="0 1 0"/>
  </joint>

  <link name="rear_caster">
    <visual>
      <geometry>
        <sphere radius="0.025"/>
      </geometry>
      <material name="gray">
        <color rgba="0.6 0.6 0.6 1.0"/>
      </material>
    </visual>
    <collision>
      <geometry>
        <sphere radius="0.025"/>
      </geometry>
    </collision>
    <inertial>
      <mass value="0.2"/>
      <origin xyz="0 0 0" rpy="0 0 0"/>
      <inertia ixx="0.0002" ixy="0" ixz="0" iyy="0.0002" iyz="0" izz="0.0002"/>
    </inertial>
  </link>

  <joint name="rear_caster_joint" type="fixed">
    <parent link="base_link"/>
    <child link="rear_caster"/>
    <origin xyz="-0.11 0 -0.075" rpy="0 0 0"/>
  </joint>

  <gazebo reference="left_wheel">
    <mu1>10.0</mu1>
    <mu2>10.0</mu2>
    <kp>1000000.0</kp>
    <kd>100.0</kd>
  </gazebo>

  <gazebo reference="right_wheel">
    <mu1>10.0</mu1>
    <mu2>10.0</mu2>
    <kp>1000000.0</kp>
    <kd>100.0</kd>
  </gazebo>

  <gazebo>
    <plugin name="gazebo_ros_diff_drive" filename="libgazebo_ros_diff_drive.so">
      <ros>
        <remapping>cmd_vel:=/cmd_vel</remapping>
        <remapping>odom:=/odom</remapping>
      </ros>

      <update_rate>50</update_rate>

      <left_joint>left_wheel_joint</left_joint>
      <right_joint>right_wheel_joint</right_joint>

      <wheel_separation>${2.0 * wheel_y}</wheel_separation>
      <wheel_diameter>${2.0 * wheel_radius}</wheel_diameter>

      <max_wheel_torque>20.0</max_wheel_torque>
      <max_wheel_acceleration>1.0</max_wheel_acceleration>

      <command_topic>cmd_vel</command_topic>

      <publish_odom>true</publish_odom>
      <publish_odom_tf>true</publish_odom_tf>
      <publish_wheel_tf>false</publish_wheel_tf>

      <odometry_topic>odom</odometry_topic>
      <odometry_frame>odom</odometry_frame>
      <robot_base_frame>base_link</robot_base_frame>
    </plugin>
  </gazebo>

</robot>